<?xml version="1.0" ?>

<robot name="m2wr" xmlns:xacro="https://www.ros.org/wiki/xacro" >
    
  <material name="black">
    <color rgba="0.0 0.0 0.0 1.0"/>
  </material>
  <material name="blue">
    <color rgba="0.203125 0.23828125 0.28515625 1.0"/>
  </material>
  <material name="green">
    <color rgba="0.0 0.8 0.0 1.0"/>
  </material>
  <material name="grey">
    <color rgba="0.2 0.2 0.2 1.0"/>
  </material>
  <material name="orange">
    <color rgba="1.0 0.423529411765 0.0392156862745 1.0"/>
  </material>
  <material name="brown">
    <color rgba="0.870588235294 0.811764705882 0.764705882353 1.0"/>
  </material>
  <material name="red">
    <color rgba="0.80078125 0.12890625 0.1328125 1.0"/>
  </material>
  <material name="white">
    <color rgba="1.0 1.0 1.0 1.0"/>
  </material>  
  
  <gazebo reference="link_chassis">
    <material>Gazebo/Blue</material>
  </gazebo>
  <gazebo reference="link_left_wheel">
    <material>Gazebo/Black</material>
  </gazebo>
  <gazebo reference="link_right_wheel">
    <material>Gazebo/Black</material>
  </gazebo>
  <gazebo reference="link_layer2">
    <material>Gazebo/Blue</material>
  </gazebo>
  <gazebo reference="support_1">
    <material>Gazebo/Green</material>
  </gazebo>
  <gazebo reference="support_2">
    <material>Gazebo/Green</material>
  </gazebo>
    <gazebo reference="support_3">
    <material>Gazebo/Green</material>
  </gazebo>
    <gazebo reference="support_4">
    <material>Gazebo/Green</material>
  </gazebo>

<gazebo>
    <plugin filename="libgazebo_ros_diff_drive.so" name="differential_drive_controller">
      <alwaysOn>true</alwaysOn>
      <updateRate>20</updateRate>
      <leftJoint>joint_left_wheel</leftJoint>
      <rightJoint>joint_right_wheel</rightJoint>
      <wheelSeparation>0.8</wheelSeparation>
      <wheelDiameter>0.2</wheelDiameter>
      <torque>10</torque>
      <commandTopic>cmd_vel</commandTopic>
      <odometryTopic>odom</odometryTopic>
      <odometryFrame>odom</odometryFrame>
      <robotBaseFrame>link_chassis</robotBaseFrame>
    </plugin>
  </gazebo>

    
  <link name="link_chassis">
    <!-- pose and inertial -->
    <!--<pose>0 0 0.1 0 0 0</pose> -->
    
    <inertial>
      <mass value="5"/>
      <origin rpy="0 0 0" xyz="0.00 0.0 0.0"/>
      <inertia ixx="0.0395416666667" ixy="0" ixz="0" iyy="0.106208333333" iyz="0" izz="0.106208333333"/>
    </inertial>
    
    <collision name="collision_chassis">
      <geometry>
        <box size="1 0.8 0.07"/>
      </geometry>
    </collision>
    
    <visual>
      <origin rpy="0 0 0" xyz="0 0 0"/>
      <geometry>
        <box size="1 0.8 0.07"/>
      </geometry>
      <material name="blue"/>
    </visual>
    
    <!-- caster front -->
    <collision name="caster_front_collision">
      <origin rpy=" 0 0 0" xyz="0.35 0 -0.05"/>
      <geometry>
        <sphere radius="0.05"/>
      </geometry>
      <surface>
        <friction>
          <ode>
            <mu>0</mu>
            <mu2>0</mu2>
            <slip1>1.0</slip1>
            <slip2>1.0</slip2>
          </ode>
        </friction>
      </surface>
    </collision>
    <visual name="caster_front_visual">
      <origin rpy=" 0 0 0" xyz="0.45 0 -0.05"/>
      <geometry>
        <sphere radius="0.05"/>
      </geometry>
    </visual>
  </link>
  
  <!-- Create wheel right -->  
    
  <link name="link_right_wheel">    
    <inertial>
      <mass value="0.2"/>
      <origin rpy="0 0 0" xyz="0 0 0"/>
      <inertia ixx="0.00052666666" ixy="0" ixz="0" iyy="0.00052666666" iyz="0" izz="0.001"/>
    </inertial>
    
    <collision name="link_right_wheel_collision">
      <origin rpy="0 1.5707 1.5707" xyz="0 0 0" />
      <geometry>
        <cylinder length="0.04" radius="0.1"/>
      </geometry>
    </collision>
    
    <visual name="link_right_wheel_visual">
    <!--Origin tag is basically for the orientation and not the offset-->
    <!-- Offset is decided when we make the joint-->
      <origin rpy="0 1.5707 1.5707" xyz="0 0 0"/>
      <geometry>
        <cylinder length="0.04" radius="0.1"/>
      </geometry>      
    </visual>
    
  </link>
    
  <!--   Joint for right wheel  -->
  <joint name="joint_right_wheel" type="continuous">
    <origin rpy="0 0 0" xyz="-0.05 0.4 0"/>
    <child link="link_right_wheel" />
    <parent link="link_chassis"/>
    <axis rpy="0 0 0" xyz="0 1 0"/>
    <limit effort="10000" velocity="1000"/>
    <joint_properties damping="1.0" friction="1.0" />
  </joint>  
    
  <!-- Left Wheel link -->
    
  <link name="link_left_wheel">    
    <inertial>
      <mass value="0.2"/>
      <origin rpy="0 0 0" xyz="0 0 0"/>
      <inertia ixx="0.00052666666" ixy="0" ixz="0" iyy="0.00052666666" iyz="0" izz="0.001"/>
    </inertial>
    
    <collision name="link_left_wheel_collision">
      <origin rpy="0 1.5707 1.5707" xyz="0 0 0" />
      <geometry>
        <cylinder length="0.04" radius="0.1"/>
      </geometry>
    </collision>
    
    <visual name="link_left_wheel_visual">
      <origin rpy="0 1.5707 1.5707" xyz="0 0 0"/>
      <geometry>
        <cylinder length="0.04" radius="0.1"/>
      </geometry>      
    </visual>
    
  </link>
    
  <!--   Joint for left wheel  -->
  <joint name="joint_left_wheel" type="continuous">
    <origin rpy="0 0 0" xyz="-0.05 -0.4 0"/>
    <child link="link_left_wheel" />
    <parent link="link_chassis"/>
    <axis rpy="0 0 0" xyz="0 1 0"/>
    <limit effort="10000" velocity="1000"/>
    <joint_properties damping="1.0" friction="1.0" />
  </joint>    

  <!--Level 2-->
  <link name="support_1">
    <!--<inertial>
      <mass value="1"/>
      <origin rpy="0.0 1.5707 0.0" xyz="-0.05 0.0 0"/>
      <inertia ixx="0.0395416666667" ixy="0" ixz="0" iyy="0.106208333333" iyz="0" izz="0.106208333333"/>
    </inertial>-->
    <visual>
      <origin rpy="0.0 1.5707 0.0" xyz="0.0 0.0 0.13"/>
      <geometry>
        <box size="0.6 0.03 0.03"/>
      </geometry>
      <material name="green"/>
    </visual>
  </link>

  <joint name="sup1" type="fixed">
    <origin xyz="0.38 0.33 0.2" rpy="0.0 0.0 0.0"/>
    <parent link="link_chassis"/>
    <child link="support_1"/>
    <axis xyz="0.0 0.0 0.0"/>
  </joint>

  <link name="support_2">
    <!--<inertial>
      <mass value="1"/>
      <origin rpy="0.0 1.5707 0.0" xyz="-0.05 0.0 0"/>
      <inertia ixx="0.0395416666667" ixy="0" ixz="0" iyy="0.106208333333" iyz="0" izz="0.106208333333"/>
    </inertial>-->
    <visual>
      <origin rpy="0.0 1.5707 0.0" xyz="0.0 0.0 0.13"/>
      <geometry>
        <box size="0.6 0.03 0.03"/>
      </geometry>
      <material name="green"/>
    </visual>
  </link>

  <joint name="sup2" type="fixed">
    <origin xyz="0.38 -0.33 0.2" rpy="0.0 0.0 0.0"/>
    <parent link="link_chassis"/>
    <child link="support_2"/>
    <axis xyz="0.0 0.0 0.0"/>
  </joint>

  <link name="support_3">
    <!--<inertial>
      <mass value="0.1"/>
      <origin rpy="0.0 1.5707 0.0" xyz="-0.05 0.0 0"/>
      <inertia ixx="0.0395416666667" ixy="0" ixz="0" iyy="0.106208333333" iyz="0" izz="0.106208333333"/>
    </inertial>-->
    <visual>
      <origin rpy="0.0 1.5707 0.0" xyz="0.0 0.0 0.13"/>
      <geometry>
        <box size="0.6 0.03 0.03"/>
      </geometry>
      <material name="green"/>
    </visual>
  </link>

  <joint name="sup3" type="fixed">
    <origin xyz="-0.38 0.33 0.2" rpy="0.0 0.0 0.0"/>
    <parent link="link_chassis"/>
    <child link="support_3"/>
    <axis xyz="0.0 0.0 0.0"/>
  </joint>

  <link name="support_4">
    <!--<inertial>
      <mass value="0.1"/>
      <origin rpy="0.0 1.5707 0.0" xyz="-0.05 0.0 0"/>
      <inertia ixx="0.0395416666667" ixy="0" ixz="0" iyy="0.106208333333" iyz="0" izz="0.106208333333"/>
    </inertial>-->
    <visual>
      <origin rpy="0.0 1.5707 0.0" xyz="0.0 0.0 0.13"/>
      <geometry>
        <box size="0.6 0.03 0.03"/>
      </geometry>
      <material name="green"/>
    </visual>
  </link>

  <joint name="sup4" type="fixed">
    <origin xyz="-0.38 -0.33 0.2" rpy="0.0 0.0 0.0"/>
    <parent link="link_chassis"/>
    <child link="support_4"/>
    <axis xyz="0.0 0.0 0.0"/>
  </joint>

  <link name="link_layer2">
    <!--<inertial>
      <mass value="1"/>
      <origin rpy="0 0 0" xyz="0 0 0.0"/>
      <inertia ixx="0.0395416666667" ixy="0" ixz="0" iyy="0.106208333333" iyz="0" izz="0.106208333333"/>
    </inertial>-->
    <visual>
      <origin rpy="0 0 0" xyz="0 0 0"/>
      <geometry>
        <box size="1 0.8 0.07"/>
      </geometry>
      <material name="blue"/>
    </visual>
  </link>

  <joint name="lay2" type="fixed">
    <origin xyz="0.0 0.0 0.6" rpy="0.0 0.0 0.0"/>
    <parent link="link_chassis"/>
    <child link="link_layer2"/>
    <axis xyz="0.0 0.0 0.0"/>
  </joint>

  <link name="link_camera">
    <visual name="">
      <origin xyz="0.0 0.0 0.0" rpy="0.0 0.0 0.0"/>
      <geometry>
        <box size="0.07 0.07 0.07"/>
      </geometry>
      <material name="red"/>
    </visual>
  </link>

  <joint name="lay2_camera" type="fixed">
    <origin xyz="0.47 0.0 0.4" rpy="0.0 0.5 0.0"/>
    <!--<origin xyz="0.23 0.0 0.07" rpy="0.0 0.4 0.0"/>-->
    <parent link="link_layer2"/>
    <child link="link_camera"/>
    <axis xyz="0.0 0.0 0.0"/>
  </joint>


  <!-- camera -->
  <gazebo reference="link_camera">
    <sensor type="camera" name="camera1">
      <update_rate>30.0</update_rate>
      <camera name="head">
        <horizontal_fov>1.3962634</horizontal_fov>
        <image>
          <width>1200</width>
          <height>800</height>
          <format>R8G8B8</format>
        </image>
        <clip>
          <near>0.02</near>
          <far>300</far>
        </clip>
        <noise>
          <type>gaussian</type>
          <!-- Noise is sampled independently per pixel on each frame.
               That pixel's noise value is added to each of its color
               channels, which at that point lie in the range [0,1]. -->
          <mean>0.0</mean>
          <stddev>0.007</stddev>
        </noise>
      </camera>
      <plugin name="camera_controller" filename="libgazebo_ros_camera.so">
        <alwaysOn>true</alwaysOn>
        <updateRate>0.0</updateRate>
        <cameraName>botcam/camera1</cameraName>
        <imageTopicName>image_raw</imageTopicName>
        <cameraInfoTopicName>camera_info</cameraInfoTopicName>
        <frameName>link_camera</frameName>
        <hackBaseline>0.07</hackBaseline>
        <distortionK1>0.0</distortionK1>
        <distortionK2>0.0</distortionK2>
        <distortionK3>0.0</distortionK3>
        <distortionT1>0.0</distortionT1>
        <distortionT2>0.0</distortionT2>
      </plugin>
    </sensor>
  </gazebo>


</robot>